<?xml version="1.0" ?>
<!-- =================================================================================== -->
<!-- |    This document was autogenerated by xacro from /media/data/helhest/src/helhest-sim/helhest_description/urdf/helhest.urdf.xacro | -->
<!-- |    EDITING THIS FILE BY HAND IS NOT RECOMMENDED                                 | -->
<!-- =================================================================================== -->
<robot name="taros-4">
  <!-- soft|omni -->
  <link name="base_link">
    <visual>
      <origin xyz="-0.047 0 0"/>
      <geometry>
        <box size="0.26 0.6 0.18"/>
      </geometry>
      <material name="base_link_color">
        <color rgba="0.1 0.1 0.1 1.0"/>
      </material>
    </visual>
    <collision>
      <origin xyz="-0.047 0 0"/>
      <geometry>
        <box size="0.26 0.6 0.18"/>
      </geometry>
    </collision>
    <inertial>
      <mass value="19"/>
      <origin rpy="0 0 0" xyz="-0.047 0 0"/>
      <inertia ixx="0.6213" ixy="0.0" ixz="0.0" iyy="0.15833333333333333" iyz="0.0" izz="0.6770333333333333"/>
    </inertial>
  </link>
  <link name="base_footprint"/>
  <joint name="base_footprint_j" type="fixed">
    <parent link="base_link"/>
    <child link="base_footprint"/>
    <origin rpy="0 0 0" xyz="0 0 -0.36"/>
  </joint>
  <link name="base_link_center"/>
  <joint name="base_link_center_j" type="fixed">
    <parent link="base_link"/>
    <child link="base_link_center"/>
    <origin rpy="0 0 0" xyz="-0.047 0 0"/>
  </joint>
  <link name="battery">
    <visual>
      <geometry>
        <box size="0.25 0.1 0.19"/>
      </geometry>
      <material name="battery_color">
        <color rgba="0.9 0.9 0.9 1.0"/>
      </material>
    </visual>
    <collision>
      <geometry>
        <box size="0.25 0.1 0.19"/>
      </geometry>
    </collision>
    <inertial>
      <mass value="2"/>
      <origin rpy="0 0 0" xyz="0 0 0"/>
      <inertia ixx="0.007683333333333334" ixy="0.0" ixz="0.0" iyy="0.01643333333333333" iyz="0.0" izz="0.012083333333333335"/>
    </inertial>
  </link>
  <joint name="battery_j" type="fixed">
    <parent link="base_link"/>
    <child link="battery"/>
    <origin rpy="0 0 0" xyz="-0.302 0.165 0"/>
  </joint>

  <!-- Motors -->
  <link name="front_left_motor">
    <visual>
      <geometry>
        <box size="0.085 0.24 0.085"/>
      </geometry>
      <material name="front_left_motor_color">
        <color rgba="0.2 0.2 0.2 1.0"/>
      </material>
    </visual>
    <collision>
      <geometry>
        <box size="0.085 0.24 0.085"/>
      </geometry>
    </collision>
    <inertial>
      <mass value="7"/>
      <origin rpy="0 0 0" xyz="0 0 0"/>
      <inertia ixx="0.037814583333333325" ixy="0.0" ixz="0.0" iyy="0.008429166666666666" iyz="0.0" izz="0.037814583333333325"/>
    </inertial>
  </link>
  <joint name="front_left_motor_j" type="fixed">
    <origin xyz="-0.09 0.14 0"/>
    <parent link="base_link"/>
    <child link="front_left_motor"/>
  </joint>

  <link name="front_right_motor">
    <visual>
      <geometry>
        <box size="0.085 0.24 0.085"/>
      </geometry>
      <material name="front_right_motor_color">
        <color rgba="0.2 0.2 0.2 1.0"/>
      </material>
    </visual>
    <collision>
      <geometry>
        <box size="0.085 0.24 0.085"/>
      </geometry>
    </collision>
    <inertial>
      <mass value="7"/>
      <origin rpy="0 0 0" xyz="0 0 0"/>
      <inertia ixx="0.037814583333333325" ixy="0.0" ixz="0.0" iyy="0.008429166666666666" iyz="0.0" izz="0.037814583333333325"/>
    </inertial>
  </link>
  <joint name="front_right_motor_j" type="fixed">
    <origin xyz="-0.09 -0.14 0"/>
    <parent link="base_link"/>
    <child link="front_right_motor"/>
  </joint>

  <link name="rear_left_motor">
    <visual>
      <geometry>
        <box size="0.085 0.24 0.085"/>
      </geometry>
      <material name="rear_left_motor_color">
        <color rgba="0.2 0.2 0.2 1.0"/>
      </material>
    </visual>
    <collision>
      <geometry>
        <box size="0.085 0.24 0.085"/>
      </geometry>
    </collision>
    <inertial>
      <mass value="7"/>
      <origin rpy="0 0 0" xyz="0 0 0"/>
      <inertia ixx="0.037814583333333325" ixy="0.0" ixz="0.0" iyy="0.008429166666666666" iyz="0.0" izz="0.037814583333333325"/>
    </inertial>
  </link>
  <joint name="rear_left_motor_j" type="fixed">
    <origin xyz="-0.79 0.14 0"/>
    <parent link="base_link"/>
    <child link="rear_left_motor"/>
  </joint>

  <link name="rear_right_motor">
    <visual>
      <geometry>
        <box size="0.085 0.24 0.085"/>
      </geometry>
      <material name="rear_right_motor_color">
        <color rgba="0.2 0.2 0.2 1.0"/>
      </material>
    </visual>
    <collision>
      <geometry>
        <box size="0.085 0.24 0.085"/>
      </geometry>
    </collision>
    <inertial>
      <mass value="7"/>
      <origin rpy="0 0 0" xyz="0 0 0"/>
      <inertia ixx="0.037814583333333325" ixy="0.0" ixz="0.0" iyy="0.008429166666666666" iyz="0.0" izz="0.037814583333333325"/>
    </inertial>
  </link>
  <joint name="rear_right_motor_j" type="fixed">
    <origin xyz="-0.79 -0.14 0"/>
    <parent link="base_link"/>
    <child link="rear_right_motor"/>
  </joint>

  <!-- Wheels -->
  <link name="front_left_wheel">
    <visual>
      <origin rpy="1.5707963267948966 0 0"/>
      <geometry>
        <cylinder length="0.11" radius="0.36"/>
      </geometry>
      <material name="front_left_wheel_color">
        <color rgba="0.2 0.2 0.2 1.0"/>
      </material>
    </visual>
    <collision>
      <origin rpy="1.5707963267948966 0 0"/>
      <geometry>
        <cylinder length="0.11" radius="0.36"/>
      </geometry>
    </collision>
    <inertial>
      <mass value="6"/>
      <origin rpy="1.5707963267948966 0 0" xyz="0 0 0"/>
      <inertia ixx="0.20045000000000002" ixy="0.0" ixz="0.0" iyy="0.20045000000000002" iyz="0.0" izz="0.38880000000000003"/>
    </inertial>
  </link>
  <joint name="front_left_wheel_j" type="continuous">
    <origin xyz="0.0 0.36 0"/>
    <parent link="base_link"/>
    <child link="front_left_wheel"/>
    <axis xyz="0 1 0"/>
  </joint>
  <ros2_control name="front_left_wheel_controller" type="system">
    <hardware>
      <plugin>gz_ros2_control/GazeboSimSystem</plugin>
    </hardware>
    <joint name="front_left_wheel_j">
      <state_interface name="velocity"/>
      <state_interface name="position"/>
      <command_interface name="velocity"/>
    </joint>
  </ros2_control>

  <link name="front_right_wheel">
    <visual>
      <origin rpy="1.5707963267948966 0 0"/>
      <geometry>
        <cylinder length="0.11" radius="0.36"/>
      </geometry>
      <material name="front_right_wheel_color">
        <color rgba="0.2 0.2 0.2 1.0"/>
      </material>
    </visual>
    <collision>
      <origin rpy="1.5707963267948966 0 0"/>
      <geometry>
        <cylinder length="0.11" radius="0.36"/>
      </geometry>
    </collision>
    <inertial>
      <mass value="6"/>
      <origin rpy="1.5707963267948966 0 0" xyz="0 0 0"/>
      <inertia ixx="0.20045000000000002" ixy="0.0" ixz="0.0" iyy="0.20045000000000002" iyz="0.0" izz="0.38880000000000003"/>
    </inertial>
  </link>
  <joint name="front_right_wheel_j" type="continuous">
    <origin xyz="0.0 -0.36 0"/>
    <parent link="base_link"/>
    <child link="front_right_wheel"/>
    <axis xyz="0 1 0"/>
  </joint>
  <ros2_control name="front_right_wheel_controller" type="system">
    <hardware>
      <plugin>gz_ros2_control/GazeboSimSystem</plugin>
    </hardware>
    <joint name="front_right_wheel_j">
      <state_interface name="velocity"/>
      <state_interface name="position"/>
      <command_interface name="velocity"/>
    </joint>
  </ros2_control>

  <link name="rear_left_wheel">
    <visual>
      <origin rpy="1.5707963267948966 0 0"/>
      <geometry>
        <cylinder length="0.11" radius="0.36"/>
      </geometry>
      <material name="rear_left_wheel_color">
        <color rgba="0.2 0.2 0.2 1.0"/>
      </material>
    </visual>
    <collision>
      <origin rpy="1.5707963267948966 0 0"/>
      <geometry>
        <cylinder length="0.11" radius="0.36"/>
      </geometry>
    </collision>
    <inertial>
      <mass value="6"/>
      <origin rpy="1.5707963267948966 0 0" xyz="0 0 0"/>
      <inertia ixx="0.20045000000000002" ixy="0.0" ixz="0.0" iyy="0.20045000000000002" iyz="0.0" izz="0.38880000000000003"/>
    </inertial>
  </link>
  <joint name="rear_left_wheel_j" type="continuous">
    <origin xyz="-0.7 0.36 0"/>
    <parent link="base_link"/>
    <child link="rear_left_wheel"/>
    <axis xyz="0 1 0"/>
  </joint>
  <ros2_control name="rear_left_wheel_controller" type="system">
    <hardware>
      <plugin>gz_ros2_control/GazeboSimSystem</plugin>
    </hardware>
    <joint name="rear_left_wheel_j">
      <state_interface name="velocity"/>
      <state_interface name="position"/>
      <command_interface name="velocity"/>
    </joint>
  </ros2_control>

  <link name="rear_right_wheel">
    <visual>
      <origin rpy="1.5707963267948966 0 0"/>
      <geometry>
        <cylinder length="0.11" radius="0.36"/>
      </geometry>
      <material name="rear_right_wheel_color">
        <color rgba="0.2 0.2 0.2 1.0"/>
      </material>
    </visual>
    <collision>
      <origin rpy="1.5707963267948966 0 0"/>
      <geometry>
        <cylinder length="0.11" radius="0.36"/>
      </geometry>
    </collision>
    <inertial>
      <mass value="6"/>
      <origin rpy="1.5707963267948966 0 0" xyz="0 0 0"/>
      <inertia ixx="0.20045000000000002" ixy="0.0" ixz="0.0" iyy="0.20045000000000002" iyz="0.0" izz="0.38880000000000003"/>
    </inertial>
  </link>
  <joint name="rear_right_wheel_j" type="continuous">
    <origin xyz="-0.7 -0.36 0"/>
    <parent link="base_link"/>
    <child link="rear_right_wheel"/>
    <axis xyz="0 1 0"/>
  </joint>
  <ros2_control name="rear_right_wheel_controller" type="system">
    <hardware>
      <plugin>gz_ros2_control/GazeboSimSystem</plugin>
    </hardware>
    <joint name="rear_right_wheel_j">
      <state_interface name="velocity"/>
      <state_interface name="position"/>
      <command_interface name="velocity"/>
    </joint>
  </ros2_control>

  <link name="left_wheel_holder">
    <visual>
      <geometry>
        <box size="0.6 0.04 0.18"/>
      </geometry>
      <material name="left_wheel_holder_color">
        <color rgba="0.8 0.8 0.8 1.0"/>
      </material>
    </visual>
    <collision>
      <geometry>
        <box size="0.6 0.04 0.18"/>
      </geometry>
    </collision>
    <inertial>
      <mass value="3"/>
      <origin rpy="0 0 0" xyz="0 0 0"/>
      <inertia ixx="0.008499999999999999" ixy="0.0" ixz="0.0" iyy="0.09809999999999999" iyz="0.0" izz="0.0904"/>
    </inertial>
  </link>
  <joint name="left_wheel_holder_j" type="fixed">
    <parent link="base_link"/>
    <child link="left_wheel_holder"/>
    <origin rpy="0 0 0" xyz="-0.477 0.095 0.0"/>
  </joint>
  <link name="right_wheel_holder">
    <visual>
      <geometry>
        <box size="0.6 0.04 0.18"/>
      </geometry>
      <material name="right_wheel_holder_color">
        <color rgba="0.8 0.8 0.8 1.0"/>
      </material>
    </visual>
    <collision>
      <geometry>
        <box size="0.6 0.04 0.18"/>
      </geometry>
    </collision>
    <inertial>
      <mass value="3"/>
      <origin rpy="0 0 0" xyz="0 0 0"/>
      <inertia ixx="0.008499999999999999" ixy="0.0" ixz="0.0" iyy="0.09809999999999999" iyz="0.0" izz="0.0904"/>
    </inertial>
  </link>
  <joint name="right_wheel_holder_j" type="fixed">
    <parent link="base_link"/>
    <child link="right_wheel_holder"/>
    <origin rpy="0 0 0" xyz="-0.477 -0.095 0.0"/>
  </joint>
  <joint name="imu_j" type="fixed">
    <parent link="base_link"/>
    <child link="imu"/>
    <origin rpy="0 0 0" xyz="0 0 0"/>
  </joint>
  <!-- workaround for https://github.com/osrf/sdformat/issues/378 -->
  <gazebo reference="imu_j">
    <preserveFixedJoint>true</preserveFixedJoint>
  </gazebo>
  <link name="imu">
    <inertial>
      <origin rpy="0 0 0" xyz="0 0 0"/>
      <mass value="1e-5"/>
      <inertia ixx="1e-3" ixy="1e-6" ixz="1e-6" iyy="1e-3" iyz="1e-6" izz="1e-3"/>
    </inertial>
    <selfCollide>false</selfCollide>
  </link>
  <gazebo reference="imu">
    <sensor name="imu" type="imu">
      <always_on>true</always_on>
      <update_rate>100</update_rate>
      <imu>
        <angular_velocity>
          <x>
            <noise type="gaussian">
              <mean>0.0</mean>
              <stddev>0.0</stddev>
            </noise>
          </x>
          <y>
            <noise type="gaussian">
              <mean>0.0</mean>
              <stddev>0.0</stddev>
            </noise>
          </y>
          <z>
            <noise type="gaussian">
              <mean>0.0</mean>
              <stddev>0.0</stddev>
            </noise>
          </z>
        </angular_velocity>
        <linear_acceleration>
          <x>
            <noise type="gaussian">
              <mean>0.0</mean>
              <stddev>0.0</stddev>
            </noise>
          </x>
          <y>
            <noise type="gaussian">
              <mean>0.0</mean>
              <stddev>0.0</stddev>
            </noise>
          </y>
          <z>
            <noise type="gaussian">
              <mean>0.0</mean>
              <stddev>0.0</stddev>
            </noise>
          </z>
        </linear_acceleration>
      </imu>
    </sensor>
  </gazebo>
</robot>